<?xml version="1.0" encoding="UTF-8"?>
<testsuite name="Google JS tests" failures="10" time="0.01">
 <testcase name="ExceptionTest.ReferenceError" time="0.01">
  <failure><![CDATA[exception_test.js:23
ReferenceError: fooBar is not defined]]></failure>
 </testcase>
 <testcase name="ExceptionTest.NotAFunctionError" time="0.01">
  <failure><![CDATA[exception_test.js:28
TypeError: object is not a function]]></failure>
 </testcase>
 <testcase name="ExceptionTest.ErrorInMatcherFactory" time="0.01">
  <failure><![CDATA[exception_test.js:32
TypeError: isNearNumber requires two number arguments]]></failure>
 </testcase>
 <testcase name="ExceptionTest.StackOverflow" time="0.01">
  <failure><![CDATA[RangeError: Maximum call stack size exceeded]]></failure>
 </testcase>
 <testcase name="ExceptionTest.UnknownPropertyOnLongFunction" time="0.01">
  <failure><![CDATA[exception_test.js:45
TypeError: Object function foo() {
    return 'asd';
  } has no method 'bar']]></failure>
 </testcase>
 <testcase name="ExceptionTest.ObjectLiteralException" time="0.01">
  <failure><![CDATA[{ name: 'SomeException' }]]></failure>
 </testcase>
 <testcase name="ExceptionTest.CustomExceptionClassWithoutStack" time="0.01">
  <failure><![CDATA[{}]]></failure>
 </testcase>
 <testcase name="ExceptionTest.CustomExceptionClassWithStack" time="0.01">
  <failure><![CDATA[exception_test.js:63
{}]]></failure>
 </testcase>
 <testcase name="ExceptionTest.CustomExceptionClassWithToString" time="0.01">
  <failure><![CDATA[SomeException]]></failure>
 </testcase>
 <testcase name="ExceptionTest.PassingTest" time="0.01"/>
 <testcase name="ThrowingConstructorTest.SomeTest" time="0.01">
  <failure><![CDATA[exception_test.js:77
Error: taco]]></failure>
 </testcase>
</testsuite>
